<robot name="my_cabinet">

  <link name="world" />
  <joint name="virtual_joint" type="fixed">
    <parent link="world" />
    <child link = "base_door_link" />
    <origin xyz="0.0 0.0 0.0" rpy="0.0 0.0 0.0" />
  </joint>

  <link name="base_door_link">
    <inertial>
      <mass value="1.0" />
      <inertia  ixx="1.0" ixy="0.0"  ixz="0.0"  iyy="100.0"  iyz="0.0"  izz="1.0" />
    </inertial>
    <visual>
      <geometry>
        <box size="0.35 0.4 0.4" />
      </geometry>
    </visual>
  </link>

  <link name="door_link">
    <inertial>
      <mass value="0.2" />
      <inertia  ixx="1.0" ixy="0.0"  ixz="0.0"  iyy="100.0"  iyz="0.0"  izz="1.0" />
    </inertial>
    <visual>
  		<origin xyz="0.0 0.2 0"/>
      <geometry>
        <box size="0.018 0.4 0.4" />
      </geometry>
    </visual>
    <collision>
  		<origin xyz="0.0 0.2 0"/>
      <geometry>
        <box size="0.018 0.4 0.4" />
      </geometry>
    </collision>
  </link>

	<joint name="joint_0" type="revolute">
		<origin xyz="0.2 -0.2 0"/>
		<axis xyz="0 0 1"/>
		<parent link="base_door_link"/>
		<child link="door_link"/>
		<limit effort="100" lower="-3.14" upper="0" velocity="100" />
	</joint>


  <gazebo reference="my_cabinet">
    <material>Gazebo/Blue</material>
  </gazebo>
</robot>