<?xml version="1.0" ?>
<robot name="my_cabinet">
	<link name="world"/>
	<joint name="virtual_joint" type="fixed">
		<parent link="world"/>
		<child link="base_cabinet_link"/>
		<origin xyz="0.0 0.0 0.0" rpy="0.0 0.0 0.0"/>
	</joint>
	<link name="base_cabinet_link">
		<visual>
			<origin xyz="0.0 0.0 -0.262" rpy="0.0 0.0 0.0"/>
			<geometry>
				<box size="0.3 0.442 0.018"/>
			</geometry>
		</visual>
		<collision>
			<origin xyz="0.0 0.0 -0.262" rpy="0.0 0.0 0.0"/>
			<geometry>
				<box size="0.3 0.442 0.018"/>
			</geometry>
		</collision>
		<visual>
			<origin xyz="0.0 0.212 0.0" rpy="0.0 0.0 0.0"/>
			<geometry>
				<box size="0.3 0.018 0.542"/>
			</geometry>
		</visual>
		<collision>
			<origin xyz="0.0 0.212 0.0" rpy="0.0 0.0 0.0"/>
			<geometry>
				<box size="0.3 0.018 0.542"/>
			</geometry>
		</collision>
		<visual>
			<origin xyz="0.0 -0.212 0.0" rpy="0.0 0.0 0.0"/>
			<geometry>
				<box size="0.3 0.018 0.542"/>
			</geometry>
		</visual>
		<collision>
			<origin xyz="0.0 -0.212 0.0" rpy="0.0 0.0 0.0"/>
			<geometry>
				<box size="0.3 0.018 0.542"/>
			</geometry>
		</collision>
		<visual>
			<origin xyz="0.0 0.0 0.262" rpy="0.0 0.0 0.0"/>
			<geometry>
				<box size="0.3 0.442 0.018"/>
			</geometry>
		</visual>
		<collision>
			<origin xyz="0.0 0.0 0.262" rpy="0.0 0.0 0.0"/>
			<geometry>
				<box size="0.3 0.442 0.018"/>
			</geometry>
		</collision>
		<visual>
			<origin xyz="-0.141 0.0 0.0" rpy="0.0 0.0 0.0"/>
			<geometry>
				<box size="0.018 0.442 0.542"/>
			</geometry>
		</visual>
		<collision>
			<origin xyz="-0.141 0.0 0.0" rpy="0.0 0.0 0.0"/>
			<geometry>
				<box size="0.018 0.442 0.542"/>
			</geometry>
		</collision>
		<inertial>
			<mass value="0.200000"/>
			<inertia ixx="0.008152" ixy="0.0" ixz="0.0" iyy="0.006396" iyz="0.0" izz="0.004756"/>
		</inertial>
	</link>
	<link name="door_link">
		<visual>
			<origin xyz="0.0 0.188 0.0"/>
			<geometry>
				<box size="0.018 0.396 0.496"/>
			</geometry>
		</visual>
		<collision>
			<origin xyz="0.0 0.188 0.0"/>
			<geometry>
				<box size="0.018 0.396 0.496"/>
			</geometry>
		</collision>
		<inertial>
			<mass value="0.200000"/>
			<inertia ixx="0.006714" ixy="0.0" ixz="0.0" iyy="0.004106" iyz="0.0" izz="0.002619"/>
		</inertial>
	</link>
	<joint name="door_joint" type="revolute">
		<origin xyz="0.141 -0.188 0" rpy="0 0 0"/>
		<axis xyz="0 0 1"/>
		<parent link="base_cabinet_link"/>
		<child link="door_link"/>
		<limit effort="50" lower="0" upper="-1.5707963267948966" velocity="10"/>
		<dynamics friction="1.0"/>
	</joint>
	<gazebo reference="my_cabinet">
		<material>Gazebo/Blue</material>
	</gazebo>
</robot>
