<?xml version="1.0" ?>
<robot name="my_cabinet">
	<link name="world"/>
	<joint name="virtual_joint" type="fixed">
		<parent link="world"/>
		<child link="base_cabinet_link"/>
		<origin xyz="0.0 0.0 0.0" rpy="0.0 0.0 0.0"/>
	</joint>
	<link name="base_cabinet_link">
		<visual>
			<origin xyz="0.0 0.0 -0.214" rpy="0.0 0.0 0.0"/>
			<geometry>
				<box size="0.3 0.346 0.018"/>
			</geometry>
		</visual>
		<collision>
			<origin xyz="0.0 0.0 -0.214" rpy="0.0 0.0 0.0"/>
			<geometry>
				<box size="0.3 0.346 0.018"/>
			</geometry>
		</collision>
		<visual>
			<origin xyz="0.0 0.16399999999999998 0.0" rpy="0.0 0.0 0.0"/>
			<geometry>
				<box size="0.3 0.018 0.446"/>
			</geometry>
		</visual>
		<collision>
			<origin xyz="0.0 0.16399999999999998 0.0" rpy="0.0 0.0 0.0"/>
			<geometry>
				<box size="0.3 0.018 0.446"/>
			</geometry>
		</collision>
		<visual>
			<origin xyz="0.0 -0.16399999999999998 0.0" rpy="0.0 0.0 0.0"/>
			<geometry>
				<box size="0.3 0.018 0.446"/>
			</geometry>
		</visual>
		<collision>
			<origin xyz="0.0 -0.16399999999999998 0.0" rpy="0.0 0.0 0.0"/>
			<geometry>
				<box size="0.3 0.018 0.446"/>
			</geometry>
		</collision>
		<visual>
			<origin xyz="0.0 0.0 0.214" rpy="0.0 0.0 0.0"/>
			<geometry>
				<box size="0.3 0.346 0.018"/>
			</geometry>
		</visual>
		<collision>
			<origin xyz="0.0 0.0 0.214" rpy="0.0 0.0 0.0"/>
			<geometry>
				<box size="0.3 0.346 0.018"/>
			</geometry>
		</collision>
		<visual>
			<origin xyz="-0.141 0.0 0.0" rpy="0.0 0.0 0.0"/>
			<geometry>
				<box size="0.018 0.346 0.446"/>
			</geometry>
		</visual>
		<collision>
			<origin xyz="-0.141 0.0 0.0" rpy="0.0 0.0 0.0"/>
			<geometry>
				<box size="0.018 0.346 0.446"/>
			</geometry>
		</collision>
		<inertial>
			<mass value="0.200000"/>
			<inertia ixx="0.005311" ixy="0.0" ixz="0.0" iyy="0.004815" iyz="0.0" izz="0.003495"/>
		</inertial>
	</link>
	<link name="door_link">
		<visual>
			<origin xyz="0.0 0.13999999999999999 0.0"/>
			<geometry>
				<box size="0.018 0.3 0.4"/>
			</geometry>
		</visual>
		<collision>
			<origin xyz="0.0 0.13999999999999999 0.0"/>
			<geometry>
				<box size="0.018 0.3 0.4"/>
			</geometry>
		</collision>
		<inertial>
			<mass value="0.200000"/>
			<inertia ixx="0.004167" ixy="0.0" ixz="0.0" iyy="0.002672" iyz="0.0" izz="0.001505"/>
		</inertial>
	</link>
	<joint name="joint_0" type="revolute">
		<origin xyz="0.141 -0.13999999999999999 0" rpy="0 0 3.141592653589793"/>
		<axis xyz="0 0 1"/>
		<parent link="base_cabinet_link"/>
		<child link="door_link"/>
		<limit effort="50" lower="-1.5707963267948966" upper="0" velocity="10"/>
		<dynamics friction="1.0"/>
	</joint>
	<gazebo reference="my_cabinet">
		<material>Gazebo/Blue</material>
	</gazebo>
</robot>
