<?xml version="1.0" ?>
<robot name="my_cabinet">
	<link name="world"/>
	<joint name="virtual_joint" type="fixed">
		<parent link="world"/>
		<child link="base_cabinet_link"/>
		<origin xyz="0.0 0.0 0.0" rpy="0.0 0.0 0.0"/>
	</joint>
	<link name="base_cabinet_link">
		<visual>
			<origin xyz="0.0 -0.0025 -0.2555" rpy="0.0 0.0 0.0"/>
			<geometry>
				<box size="0.4 0.448 0.018"/>
			</geometry>
		</visual>
		<collision name="base_cabinet_link_collision_0">
			<origin xyz="0.0 -0.0025 -0.2555" rpy="0.0 0.0 0.0"/>
			<geometry>
				<box size="0.4 0.448 0.018"/>
			</geometry>
		</collision>
		<visual>
			<origin xyz="0.0 0.21250000000000002 0.0" rpy="0.0 0.0 0.0"/>
			<geometry>
				<box size="0.4 0.018 0.529"/>
			</geometry>
		</visual>
		<collision name="base_cabinet_link_collision_1">
			<origin xyz="0.0 0.21250000000000002 0.0" rpy="0.0 0.0 0.0"/>
			<geometry>
				<box size="0.4 0.018 0.529"/>
			</geometry>
		</collision>
		<visual>
			<origin xyz="0.0 -0.21750000000000003 0.0" rpy="0.0 0.0 0.0"/>
			<geometry>
				<box size="0.4 0.018 0.529"/>
			</geometry>
		</visual>
		<collision name="base_cabinet_link_collision_2">
			<origin xyz="0.0 -0.21750000000000003 0.0" rpy="0.0 0.0 0.0"/>
			<geometry>
				<box size="0.4 0.018 0.529"/>
			</geometry>
		</collision>
		<visual>
			<origin xyz="0.0 -0.0025 0.2555" rpy="0.0 0.0 0.0"/>
			<geometry>
				<box size="0.4 0.448 0.018"/>
			</geometry>
		</visual>
		<collision name="base_cabinet_link_collision_3">
			<origin xyz="0.0 -0.0025 0.2555" rpy="0.0 0.0 0.0"/>
			<geometry>
				<box size="0.4 0.448 0.018"/>
			</geometry>
		</collision>
		<visual>
			<origin xyz="-0.191 -0.0025 0.0" rpy="0.0 0.0 0.0"/>
			<geometry>
				<box size="0.018 0.448 0.529"/>
			</geometry>
		</visual>
		<collision name="base_cabinet_link_collision_4">
			<origin xyz="-0.191 -0.0025 0.0" rpy="0.0 0.0 0.0"/>
			<geometry>
				<box size="0.018 0.448 0.529"/>
			</geometry>
		</collision>
		<inertial>
			<mass value="0.200000"/>
			<inertia ixx="0.008009" ixy="0.0" ixz="0.0" iyy="0.007331" iyz="0.0" izz="0.006012"/>
		</inertial>
	</link>
	<link name="door_link">
		<visual>
			<origin xyz="0.0 -0.1985 0.0"/>
			<geometry>
				<box size="0.018 0.397 0.483"/>
			</geometry>
		</visual>
		<collision name="door_link_collision">
			<origin xyz="0.0 -0.1985 0.0"/>
			<geometry>
				<box size="0.018 0.397 0.483"/>
			</geometry>
		</collision>
		<inertial>
			<mass value="0.200000"/>
			<inertia ixx="0.006515" ixy="0.0" ixz="0.0" iyy="0.003894" iyz="0.0" izz="0.002632"/>
		</inertial>
	</link>
	<joint name="door_joint" type="revolute">
		<origin xyz="0.191 -0.1985 0.0" rpy="0.000000 -0.000000 3.141593"/>
		<axis xyz="0 0 1"/>
		<parent link="base_cabinet_link"/>
		<child link="door_link"/>
		<limit effort="50" lower="-1.658062789394613" upper="0" velocity="10"/>
		<dynamics friction="3.5" damping="3.5"/>
	</joint>
	<gazebo reference="base_cabinet_link">
		<sensor name="main_sensor" type="contact">
			<selfCollide>true</selfCollide>
			<alwaysOn>true</alwaysOn>
			<updateRate>5.0</updateRate>
			<material>Gazebo/Red</material>
			<contact>
				<collision>base_cabinet_link_collision_0_collision</collision>
				<collision>base_cabinet_link_collision_1_collision</collision>
				<collision>base_cabinet_link_collision_2_collision</collision>
				<collision>base_cabinet_link_collision_3_collision</collision>
				<collision>base_cabinet_link_collision_4_collision</collision>
			</contact>
			<plugin name="gazebo_ros_bumper_controller" filename="libgazebo_ros_bumper.so">
				<bumperTopicName>/contact</bumperTopicName>
				<frameName>world</frameName>
			</plugin>
		</sensor>
	</gazebo>
	<gazebo reference="door_link">
		<sensor name="main_sensor" type="contact">
			<selfCollide>true</selfCollide>
			<alwaysOn>true</alwaysOn>
			<updateRate>5.0</updateRate>
			<material>Gazebo/Red</material>
			<contact>
				<collision>door_link_collision_collision</collision>
			</contact>
			<plugin name="gazebo_ros_bumper_controller" filename="libgazebo_ros_bumper.so">
				<bumperTopicName>/contact_door</bumperTopicName>
				<frameName>contact_door</frameName>
			</plugin>
		</sensor>
	</gazebo>
	<gazebo reference="door_link">
		<mu>3.0</mu>
		<mu2>3.0</mu2>
		<kp>10000000</kp>
		<kd>100</kd>
	</gazebo>
</robot>
